Workbook

Sheet 日淘
A1: IP | B1: 系列名称 | C1: 名称 | D1: 买时状态 | E1: 购入价格 | F1: 运费 | G1: 状态 | H1: 缴税 | I1: 总价 | J1: 成本价格 | K1: 卖出价格 | L1: 利润 | M1: 利润率 | N1: 备注 | O1: 卖否 | P1: 转运单号
A2: 龙珠 | B2: MSP | C2: 超赛悟空 | D2: 拆摆 | E2: 153 | F2: 41 | G2: 卖出 | I2: =(E2+F2+H2) -> 194 | J2: 194 | K2: 165 | L2: =(K2-J2) -> -29 | M2: =ROUND(L2/J2,4) -> -0.1495
A3: 龙珠 | B3: Grandista | C3: 超赛贝吉塔 | D3: 拆摆 | E3: 433 | F3: 84 | G3: 留存 | I3: =(E3+F3+H3) -> 517 | Q3: 总花销 | R3: =SUM(I:I) -> 148144
A4: 龙珠 | B4: 武道会3 | C4: 人造人18号 | D4: 拆摆 | E4: 230 | F4: 23 | G4: 留存 | I4: =(E4+F4+H4) -> 253 | Q4: 总卖出 | R4: =SUM(K:K) -> 95089
A5: 龙珠 | B5: Grandista | C5: 超赛悟空 | D5: 全新 | E5: 435 | F5: 73 | G5: 留存 | H5: 17 | I5: =(E5+F5+H5) -> 525 | Q5: 总卖出成本 | R5: =SUM(J:J) -> 84382
A6: 龙珠 | B6: MSP | C6: 超赛悟空 | D6: 全新 | E6: 194 | F6: 50 | G6: 留存 | H6: 17 | I6: =(E6+F6+H6) -> 261 | Q6: 利润 | R6: =SUM(L:L) -> 10707
A7: 龙珠 | B7: 武道会3 | C7: 龟仙人 | D7: 拆摆 | E7: 397 | F7: 28 | G7: 留存 | H7: 17 | I7: =(E7+F7+H7) -> 442 | Q7: 利润率 | R7: =ROUND(R6/R5,4) -> 0.1269
A8: 龙珠 | B8: 一番赏 | C8: 宇航服悟饭克林 | D8: 全新 | E8: 242 | F8: 62 | G8: 卖出 | I8: =(E8+F8+H8) -> 304 | J8: =I8 -> 304 | K8: 365 | L8: =(K8-J8) -> 61 | M8: =ROUND(L8/J8,4) -> 0.2007 | N8: set | Q8: 实际支出 | R8: =R3-R4 -> 53055
A9: 龙珠 | B9: SMSP | C9: 棍空C赏 | D9: 拆摆 | E9: 855 | F9: 27 | G9: 卖出 | H9: 19 | I9: =(E9+F9+H9) -> 901 | J9: =I9 -> 901 | K9: 1100 | L9: =(K9-J9) -> 199 | M9: =ROUND(L9/J9,4) -> 0.2209
A10: 龙珠 | B10: MSP | C10: 超赛特兰克斯 | D10: 拆摆 | E10: 271 | F10: 27 | G10: 留存 | H10: 19 | I10: =(E10+F10+H10) -> 317
A11: 鬼灭之刃 | B11: 一番赏 | C11: 甘露寺蜜璃A赏 | D11: 全新 | E11: 133 | F11: 15 | G11: 留存 | H11: 19 | I11: =(E11+F11+H11) -> 167
A12: 鬼灭之刃 | B12: 一番赏 | C12: 时透无一郎B赏 | D12: 全新 | E12: 178 | F12: 12 | G12: 留存 | H12: 19 | I12: =(E12+F12+H12) -> 209
A13: 龙珠 | B13: 一番赏 | C13: 激突 （小布欧+悟饭+赛亚超人悟饭+达普拉） | D13: 全新 | E13: 1125 | F13: 99 | G13: 留存 | H13: 70 | I13: =(E13+F13+H13) -> 1294 | N13: set
A14: 龙珠 | B14: SMSP | C14: 棍空C赏 | D14: 全新 | E14: 1075 | F14: 50 | G14: 卖出 | H14: 19 | I14: =(E14+F14+H14) -> 1144 | J14: =I14 -> 1144 | K14: 1160 | L14: =(K14-J14) -> 16 | M14: =ROUND(L14/J14,4) -> 0.014
A15: 龙珠 | B15: 一番赏 | C15: 多多利亚 | D15: 拆摆 | E15: 401 | F15: 82 | G15: 卖出 | H15: 19 | I15: =(E15+F15+H15) -> 502 | J15: =I15 -> 502 | K15: 679 | L15: =(K15-J15) -> 177 | M15: =ROUND(L15/J15,4) -> 0.3526 | N15: 无桩
A16: 沙漠大冒险 | B16: 一番赏 | C16: 贝尔杰布A赏 | D16: 全新 | E16: 262 | F16: 17 | G16: 卖出 | H16: 19 | I16: =(E16+F16+H16) -> 298 | J16: 298 | K16: 298 | L16: =(K16-J16) -> 0 | M16: =ROUND(L16/J16,4) -> 0
A17: 沙漠大冒险 | B17: 一番赏 | C17: 贝尔杰布A赏 | D17: 全新 | E17: 265 | F17: 18 | G17: 留存 | H17: 19 | I17: =(E17+F17+H17) -> 302
A18: 龙珠 | B18: LC | C18: 特兰克斯 | D18: 全新 | E18: 248 | F18: 18 | G18: 留存 | H18: 46 | I18: =(E18+F18+H18) -> 312
A19: 龙珠 | B19: 一番赏 | C19: 弗利萨第二形态 | D19: 全新 | E19: 287 | F19: 41 | G19: 卖出 | H19: 46 | I19: =(E19+F19+H19) -> 374 | J19: =I19 -> 374 | K19: 440 | L19: =(K19-J19) -> 66 | M19: =ROUND(L19/J19,4) -> 0.1765
A20: 龙珠 | B20: PLEX | C20: 弗利萨第三形态 | D20: 全新 | E20: 1736 | F20: 62 | G20: 卖出 | H20: 47 | I20: =(E20+F20+H20) -> 1845 | J20: 1845 | K20: 2300 | L20: =(K20-J20) -> 455 | M20: =ROUND(L20/J20,4) -> 0.2466 | N20: 特典版
A21: 龙珠 | B21: 一番赏 | C21: LB悟空最终赏 | D21: 全新 | E21: 401 | F21: 54 | G21: 留存 | H21: 47 | I21: =(E21+F21+H21) -> 502
A22: 龙珠 | B22: 一番赏 | C22: LB悟空最终赏 | D22: 内袋未拆 | E22: 383 | F22: 69 | G22: 卖出 | H22: 25 | I22: =(E22+F22+H22) -> 477 | J22: =I22 -> 477 | K22: 540 | L22: =(K22-J22) -> 63 | M22: =ROUND(L22/J22,4) -> 0.1321
A23: 龙珠 | B23: PLEX | C23: 弗利萨第三形态 | D23: 拆摆 | E23: 1159 | F23: 77 | G23: 卖出 | H23: 25 | I23: =(E23+F23+H23) -> 1261 | J23: =I23 -> 1261 | K23: 1560 | L23: =(K23-J23) -> 299 | M23: =ROUND(L23/J23,4) -> 0.2371 | N23: 普通版
A24: 龙珠 | B24: 一番赏 | C24: 宇航服布玛 | D24: 全新 | E24: 307 | F24: 34 | G24: 卖出 | H24: 25 | I24: =(E24+F24+H24) -> 366 | J24: =I24 -> 366 | K24: 392 | L24: =(K24-J24) -> 26 | M24: =ROUND(L24/J24,4) -> 0.071
A25: 龙珠 | B25: SMSP | C25: 棍空C赏 | D25: 全新 | E25: 972 | F25: 54 | G25: 留存 | H25: 27 | I25: =(E25+F25+H25) -> 1053
A26: 龙珠 | B26: 一番赏 | C26: 宇航服悟饭克林 | D26: 全新 | E26: 245 | F26: 29 | G26: 卖出 | H26: 27 | I26: =(E26+F26+H26) -> 301 | J26: 301 | K26: 399 | L26: =(K26-J26) -> 98 | M26: =ROUND(L26/J26,4) -> 0.3256 | N26: set
A27: 龙珠 | B27: 一番赏 | C27: 宇航服悟饭克林 | D27: 全新 | E27: 253 | F27: 30 | G27: 卖出 | H27: 27 | I27: =(E27+F27+H27) -> 310 | J27: 310 | K27: 379 | L27: =(K27-J27) -> 69 | M27: =ROUND(L27/J27,4) -> 0.2226 | N27: set
A28: 龙珠 | B28: 一番赏 | C28: 宇航服布玛 | D28: 全新 | E28: 234 | F28: 37 | G28: 卖出 | H28: 27 | I28: =(E28+F28+H28) -> 298 | J28: =I28 -> 298 | K28: 384 | L28: =(K28-J28) -> 86 | M28: =ROUND(L28/J28,4) -> 0.2886
A29: 龙珠 | B29: PLEX | C29: 大长老 | D29: 全新 | E29: 3846 | F29: 225 | G29: 卖出 | H29: 89 | I29: =(E29+F29+H29) -> 4160 | J29: 4160 | K29: 3400 | L29: =(K29-J29) -> -760 | M29: =ROUND(L29/J29,4) -> -0.1827 | N29: 特典版
A30: 龙珠 | B30: 一番赏 | C30: 邱夷 | D30: 全新 | E30: 327 | F30: 18 | G30: 卖出 | I30: =(E30+F30+H30) -> 345 | J30: 345 | K30: 429 | L30: =(K30-J30) -> 84 | M30: =ROUND(L30/J30,4) -> 0.2435
A31: 龙珠 | B31: 一番赏 | C31: 邱夷 | D31: 全新 | E31: 323 | F31: 18 | G31: 卖出 | I31: =(E31+F31+H31) -> 341 | J31: 341 | K31: 450 | L31: =(K31-J31) -> 109 | M31: =ROUND(L31/J31,4) -> 0.3196
A32: 龙珠 | B32: 一番赏 | C32: 多多利亚 | D32: 全新 | E32: 551 | F32: 58 | G32: 留存 | I32: =(E32+F32+H32) -> 609
A33: 龙珠 | B33: 一番赏 | C33: 宇航服悟饭克林 | D33: 全新 | E33: 278 | F33: 29 | G33: 卖出 | H33: 38 | I33: =(E33+F33+H33) -> 345 | J33: 345 | K33: 386 | L33: =(K33-J33) -> 41 | M33: =ROUND(L33/J33,4) -> 0.1188 | N33: set
A34: 龙珠 | B34: 一番赏 | C34: lb贝吉塔 | D34: 全新 | E34: 747 | F34: 38 | G34: 卖出 | H34: 38 | I34: =(E34+F34+H34) -> 823 | J34: 823 | K34: 950 | L34: =(K34-J34) -> 127 | M34: =ROUND(L34/J34,4) -> 0.1543 | N34: 盒有轻损
A35: 龙珠 | B35: 一番赏 | C35: 宇航服布玛 | D35: 全新 | E35: 278 | F35: 34 | G35: 卖出 | H35: 38 | I35: =(E35+F35+H35) -> 350 | J35: =I35 -> 350 | K35: 386 | L35: =(K35-J35) -> 36 | M35: =ROUND(L35/J35,4) -> 0.1029
A36: 龙珠 | B36: PLEX | C36: 弗利萨第三形态 | D36: 全新 | E36: 1765 | F36: 74 | G36: 卖出 | H36: 39 | I36: =(E36+F36+H36) -> 1878 | J36: 1878 | K36: 2100 | L36: =(K36-J36) -> 222 | M36: =ROUND(L36/J36,4) -> 0.1182 | N36: 特典版
A37: 龙珠 | B37: 一番赏 | C37: 宇航服悟饭克林 | D37: 全新 | E37: 249 | F37: 32 | G37: 卖出 | H37: 36 | I37: =(E37+F37+H37) -> 317 | J37: 317 | K37: 399 | L37: =(K37-J37) -> 82 | M37: =ROUND(L37/J37,4) -> 0.2587 | N37: set
A38: 龙珠 | B38: 一番赏 | C38: 宇航服悟饭克林 | D38: 全新 | E38: 246 | F38: 33 | G38: 卖出 | H38: 36 | I38: =(E38+F38+H38) -> 315 | J38: 315 | K38: 395 | L38: =(K38-J38) -> 80 | M38: =ROUND(L38/J38,4) -> 0.254 | N38: set
A39: 龙珠 | B39: PLEX | C39: 弗利萨第三形态 | D39: 全新 | E39: 1696 | F39: 81 | G39: 卖出 | H39: 37 | I39: =(E39+F39+H39) -> 1814 | J39: 1814 | K39: 2129 | L39: =(K39-J39) -> 315 | M39: =ROUND(L39/J39,4) -> 0.1736 | N39: 特典版
A40: 偶像大师灰姑娘女孩 | B40: Alter | C40: 宫本芙蕾德莉卡 | D40: 全新 | E40: 724 | F40: 19 | G40: 留存 | H40: 37 | I40: =(E40+F40+H40) -> 780
...

Sheet 闲鱼
A1: IP | B1: 系列名称 | C1: 名称 | D1: 买时状态 | E1: 购入价格 | F1: 运费 | G1: 状态 | H1: 总价 | I1: 成本价格 | J1: 卖出价格 | K1: 利润 | L1: 利润率 | M1: 备注
A2: 数码宝贝 | B2: FRS | C2: 机械邪龙 | D2: 全新 | E2: 330 | G2: 留存 | H2: =(E2+F2) -> 330 | O2: 总花销 | P2: =SUM(H:H) -> 52787
A3: 龙珠 | B3: HG | C3: 基纽特战队 | D3: 拆摆 | E3: 580 | G3: 留存 | H3: =(E3+F3) -> 580 | O3: 总卖出 | P3: =SUM(J:J) -> 5066
A4: 龙珠 | B4: 一番赏 | C4: 基纽 | D4: 全新 | E4: 350 | F4: 45 | G4: 留存 | H4: =(E4+F4) -> 395 | M4: 入坑第一个 | O4: 总卖出成本 | P4: =SUM(I:I) -> 4786
A5: 龙珠 | B5: 一番赏 | C5: 那巴B赏 | D5: 全新 | E5: 168 | G5: 留存 | H5: =(E5+F5) -> 168 | O5: 利润 | P5: =SUM(K:K) -> 280
A6: 鬼灭之刃 | B6: 一番赏 | C6: 炼狱杏寿郎 | D6: 全新 | E6: 214 | G6: 留存 | H6: =(E6+F6) -> 214 | O6: 利润率 | P6: =ROUND(P5/P4,4) -> 0.0585
A7: 鬼灭之刃 | B7: 一番赏 | C7: 富冈义勇 | D7: 全新 | E7: 200 | G7: 留存 | H7: =(E7+F7) -> 200 | O7: 实际支出 | P7: =P2-P3 -> 47721
A8: 鬼灭之刃 | B8: 一番赏 | C8: 蝴蝶忍 | D8: 全新 | E8: 229 | G8: 留存 | H8: =(E8+F8) -> 229
A9: 龙珠 | B9: 一番赏 | C9: 蔬菜人 | D9: 拆摆 | E9: 58 | G9: 留存 | H9: =(E9+F9) -> 58
A10: 龙珠 | B10: 武道会 | C10: 兰琪 | D10: 全新 | E10: 185 | G10: 留存 | H10: =(E10+F10) -> 185
A11: 龙珠 | B11: 一番赏 | C11: 波伦伽 | D11: 拆摆 | E11: 1266 | G11: 留存 | H11: =(E11+F11) -> 1266
A12: 龙珠 | B12: 一番赏 | C12: 抬头龙 | D12: 全新 | E12: 1079 | G12: 留存 | H12: =(E12+F12) -> 1079
A13: 龙珠 | B13: MSP | C13: 悟天克斯 | D13: 全新 | E13: 225 | G13: 留存 | H13: =(E13+F13) -> 225
A14: 龙珠 | B14: BWFC | C14: 虎皮悟空 | D14: 全新 | E14: 226 | F14: 11 | G14: 留存 | H14: =(E14+F14) -> 237
A15: 龙珠 | B15: BWFC | C15: 打伞悟空 | D15: 全新 | E15: 226 | F15: 11 | G15: 留存 | H15: =(E15+F15) -> 237
A16: 龙珠 | B16: 一番赏 | C16: 雅木茶 | D16: 拆摆 | E16: 279 | G16: 留存 | H16: =(E16+F16) -> 279
A17: 龙珠 | B17: 一番赏 | C17: 地球比克 | D17: 拆摆 | E17: 186 | G17: 留存 | H17: =(E17+F17) -> 186
A18: 鬼灭之刃 | B18: Grandista | C18: 善逸 | D18: 全新 | E18: 50 | G18: 留存 | H18: =(E18+F18) -> 50
A19: 龙珠 | B19: 武道会4 | C19: 布玛 | D19: 拆摆 | E19: 560 | G19: 留存 | H19: =(E19+F19) -> 560
A20: 龙珠 | B20: 一番赏 | C20: 胖布欧 | D20: 拆摆 | E20: 700 | G20: 留存 | H20: =(E20+F20) -> 700
A21: 龙珠 | B21: 造型驿传 | C21: 父子摸头 | D21: 全新 | E21: 298 | F21: 20 | G21: 留存 | H21: =(E21+F21) -> 318
A22: 龙珠 | B22: 超像 | C22: 悟空 | D22: 全新 | E22: 500 | G22: 留存 | H22: =(E22+F22) -> 500
A23: 龙珠 | B23: 一番赏 | C23: 地球库林 | D23: 拆摆 | E23: 300 | G23: 留存 | H23: =(E23+F23) -> 300
A24: 龙珠 | B24: 一番赏 | C24: 眼镜悟饭 | D24: 拆摆 | E24: 200 | G24: 留存 | H24: =(E24+F24) -> 200
A25: 龙珠 | B25: 一番赏 | C25: 书包芳芳 | D25: 拆摆 | E25: 100 | G25: 留存 | H25: =(E25+F25) -> 100
A26: 龙珠 | B26: 一番赏 | C26: 贝吉塔大猿 | D26: 拆摆 | E26: 1218 | G26: 卖出 | H26: =(E26+F26) -> 1218 | I26: 1218 | J26: 1179 | K26: =J26-I26 -> -39 | L26: =K26/I26 -> -0.032019704
A27: 龙珠 | B27: Collection | C27: 库林 | D27: 全新 | E27: 85 | G27: 留存 | H27: =(E27+F27) -> 85
A28: 龙珠 | B28: 一番赏 | C28: 野兽悟饭 | D28: 全新 | E28: 120 | G28: 留存 | H28: =(E28+F28) -> 120
A29: 龙珠 | B29: Grandista | C29: 桃红悟空 | D29: 全新 | E29: 120 | G29: 留存 | H29: =(E29+F29) -> 120
A30: 龙珠 | B30: Gxmateria | C30: 弗利萨 | D30: 全新 | E30: 135 | G30: 留存 | H30: =(E30+F30) -> 135
A31: 龙珠 | B31: FiguartsZERO | C31: 超3龙拳 | D31: 全新 | E31: 770 | G31: 留存 | H31: =(E31+F31) -> 770 | M31: 初版
A32: 龙珠 | B32: 武道会2 | C32: 桃白白 | D32: 全新 | E32: 330 | G32: 留存 | H32: =(E32+F32) -> 330
A33: 龙珠 | B33: 一番赏 | C33: 休闲服悟空 | D33: 全新 | E33: 250 | G33: 留存 | H33: =(E33+F33) -> 250
A34: 龙珠 | B34: 一番赏 | C34: 那巴最终赏 | D34: 拆摆 | E34: 166 | G34: 留存 | H34: =(E34+F34) -> 166
A35: 龙珠 | B35: 一番赏 | C35: 红发贝吉塔+小芳 | D35: 全新 | E35: 340 | G35: 留存 | H35: =(E35+F35) -> 340 | M35: set
A36: 龙珠 | B36: 一番赏 | C36: 肌肉沙鲁 | D36: 全新 | E36: 500 | G36: 留存 | H36: =(E36+F36) -> 500
A37: 龙珠 | B37: 必杀技 | C37: 蓝发贝吉塔+扎马斯 | D37: 全新 | E37: 350 | G37: 留存 | H37: =(E37+F37) -> 350
A38: 龙珠 | B38: 必杀技 | C38: 龟派气功孙悟空 | D38: 拆摆 | E38: 180 | G38: 卖出 | H38: =(E38+F38) -> 180 | I38: 180 | J38: 149 | K38: =J38-I38 -> -31 | L38: =K38/I38 -> -0.17222222
A39: 龙珠 | B39: 必杀技 | C39: 贝吉塔 | D39: 全新 | E39: 120 | G39: 留存 | H39: =(E39+F39) -> 120 | M39: 盒损内袋未拆
A40: 龙珠 | B40: BWFC | C40: 军装悟空 | D40: 全新 | E40: 230 | G40: 留存 | H40: =(E40+F40) -> 230
...

Sheet 泡泡玛特
A1: IP | B1: 系列名称 | C1: 名称 | D1: 买时状态 | E1: 购入价格 | F1: 状态 | G1: 卖出成本 | H1: 卖出价格 | I1: 利润 | J1: 利润率 | K1: 渠道 | L1: 备注
A2: 泡泡玛特 | B2: LABUBU | C2: 大夏日 | D2: 全新 | E2: 498 | F2: 卖出 | G2: 498 | H2: 527 | I2: =H2-G2 -> 29 | J2: =I2/G2 -> 0.058232932 | K2: 京东 | N2: 总花销 | O2: =SUM(E:E) -> 23689
A3: 泡泡玛特 | B3: LABUBU | C3: 象棋国王 | D3: 全新 | E3: 499 | F3: 卖出 | G3: 499 | H3: 676 | I3: =H3-G3 -> 177 | J3: =I3/G3 -> 0.35470942 | K3: 小程序 | N3: 总卖出 | O3: =SUM(H:H) -> 31233
A4: 泡泡玛特 | B4: LABUBU | C4: 象棋国王+皇后 | D4: 全新 | E4: 658 | F4: 卖出 | G4: 658 | H4: 894 | I4: =H4-G4 -> 236 | J4: =I4/G4 -> 0.35866261 | K4: 淘宝 | L4: 胖猪号 | N4: 总卖出成本 | O4: =SUM(G:G) -> 20505
A5: 泡泡玛特 | B5: LABUBU | C5: MOKOKO 甜心挂件 | D5: 全新 | E5: 99 | F5: 卖出 | G5: 99 | H5: 447 | I5: =H5-G5 -> 348 | J5: =I5/G5 -> 3.5151515 | K5: 小程序 | N5: 利润 | O5: =SUM(I:I) -> 10728
A6: 泡泡玛特 | B6: LABUBU | C6: ZIMOMO 大首领 | D6: 全新 | E6: 999 | F6: 卖出 | G6: 999 | H6: 1402 | I6: =H6-G6 -> 403 | J6: =I6/G6 -> 0.4034034 | K6: 小程序 | N6: 利润率 | O6: =ROUND(O5/O4,4) -> 0.5232
A7: 泡泡玛特 | B7: LABUBU | C7: 一代黑皮 | D7: 全新 | E7: 399 | F7: 卖出 | G7: 399 | H7: 466 | I7: =H7-G7 -> 67 | J7: =I7/G7 -> 0.1679198 | K7: 小程序 | N7: 实际支出 | O7: =O2-O3 -> -7544
A8: 泡泡玛特 | B8: LABUBU | C8: 坐坐 | D8: 全新 | E8: 99 | F8: 卖出 | G8: 99 | H8: 105 | I8: =H8-G8 -> 6 | J8: =I8/G8 -> 0.060606061 | K8: 抖音
A9: 泡泡玛特 | B9: LABUBU | C9: 大春野 | D9: 全新 | E9: 499 | F9: 留存 | K9: 小程序
A10: 泡泡玛特 | B10: LABUBU | C10: 象棋皇后 | D10: 全新 | E10: 149 | F10: 留存 | K10: 小程序
A11: 泡泡玛特 | B11: LABUBU | C11: 象棋皇后 | D11: 全新 | E11: 149 | F11: 留存 | K11: 小程序 | L11: 门店
A12: 泡泡玛特 | B12: LABUBU | C12: MOKOKO 甜心 | D12: 全新 | E12: 399 | F12: 卖出 | G12: 399 | H12: 865 | I12: =H12-G12 -> 466 | J12: =I12/G12 -> 1.1679198 | K12: 小程序
A13: 泡泡玛特 | B13: LABUBU | C13: 3.0 | D13: 全新 | E13: 594 | F13: 卖出 | G13: 594 | H13: 944 | I13: =H13-G13 -> 350 | J13: =I13/G13 -> 0.58922559 | K13: 小程序 | L13: 胖猪号，整端
A14: 泡泡玛特 | B14: LABUBU | C14: 坐坐 | D14: 全新 | E14: 594 | F14: 卖出 | G14: 594 | H14: 646 | I14: =H14-G14 -> 52 | J14: =I14/G14 -> 0.087542088 | K14: 小程序 | L14: 整端
A15: 泡泡玛特 | B15: LABUBU | C15: 象棋国王 | D15: 全新 | E15: 499 | F15: 卖出 | K15: 小程序 | L15: 送小孔
A16: 泡泡玛特 | B16: LABUBU | C16: MOKOKO 甜心 | D16: 全新 | E16: 399 | F16: 留存 | K16: 小程序 | L16: 范姐号
A17: 泡泡玛特 | B17: Molly | C17: BabyMolly | D17: 全新 | E17: 474 | F17: 卖出 | G17: 474 | H17: 656 | I17: =H17-G17 -> 182 | J17: =I17/G17 -> 0.38396624 | K17: 淘宝 | L17: 胖猪号
A18: 泡泡玛特 | B18: Molly | C18: BabyMolly | D18: 全新 | E18: 474 | F18: 卖出 | G18: 474 | H18: 695 | I18: =H18-G18 -> 221 | J18: =I18/G18 -> 0.46624473 | K18: 淘宝
A19: 泡泡玛特 | B19: LABUBU | C19: 坐坐 | D19: 全新 | E19: 594 | F19: 卖出 | G19: 592 | H19: 899 | I19: =H19-G19 -> 307 | J19: =I19/G19 -> 0.51858108 | K19: 小程序 | L19: 整端
A20: 泡泡玛特 | B20: LABUBU | C20: 马卡龙 | D20: 全新 | E20: 592 | F20: 卖出 | G20: 592 | H20: 1491 | I20: =H20-G20 -> 899 | J20: =I20/G20 -> 1.5185811 | K20: 小程序 | L20: 整端
A21: 泡泡玛特 | B21: LABUBU | C21: 森林童话 | D21: 全新 | F21: 留存 | K21: 小程序 | L21: 5000积分，自留已拆
A22: 泡泡玛特 | B22: LABUBU | C22: 森林童话 | D22: 全新 | F22: 留存 | K22: 小程序 | L22: 5000积分
A23: 泡泡玛特 | B23: LABUBU | C23: 3.0 | D23: 全新 | E23: 594 | F23: 卖出 | G23: 594 | H23: 1243 | I23: =H23-G23 -> 649 | J23: =I23/G23 -> 1.0925926 | K23: 小程序 | L23: 7月28日，整端
A24: 泡泡玛特 | B24: LABUBU | C24: 3.0 | D24: 全新 | E24: 594 | F24: 卖出 | G24: 594 | H24: 850 | I24: =H24-G24 -> 256 | J24: =I24/G24 -> 0.43097643 | K24: 小程序 | L24: 9月22日，整端
A25: 泡泡玛特 | B25: LABUBU | C25: 可乐 | D25: 全新 | E25: 159 | F25: 卖出 | G25: 159 | H25: 180 | I25: =H25-G25 -> 21 | J25: =I25/G25 -> 0.13207547 | K25: 小程序
A26: 泡泡玛特 | B26: LABUBU | C26: 3.0 | D26: 全新 | E26: 594 | F26: 卖出 | G26: 594 | H26: 1143 | I26: =H26-G26 -> 549 | J26: =I26/G26 -> 0.92424242 | K26: 淘宝 | L26: 胖猪号，整端
A27: 泡泡玛特 | B27: LABUBU | C27: 3.0 | D27: 全新 | E27: 594 | F27: 卖出 | G27: 594 | H27: 1143 | I27: =H27-G27 -> 549 | J27: =I27/G27 -> 0.92424242 | K27: 淘宝 | L27: 胖猪号，整端
A28: 泡泡玛特 | B28: LABUBU | C28: 便利店 | D28: 全新 | E28: 69 | F28: 卖出 | G28: 69 | H28: 107 | I28: =H28-G28 -> 38 | J28: =I28/G28 -> 0.55072464 | K28: 盒机 | L28: 沙拉
A29: 泡泡玛特 | B29: LABUBU | C29: 便利店 | D29: 全新 | E29: 69 | F29: 卖出 | G29: 69 | H29: 70 | I29: =H29-G29 -> 1 | J29: =I29/G29 -> 0.014492754 | K29: 盒机 | L29: 胖猪号，香肠
A30: 泡泡玛特 | B30: SKULL PANDA | C30: 2.0 | D30: 全新 | E30: 1161 | F30: 卖出 | G30: 1161 | H30: 1223 | I30: =H30-G30 -> 62 | J30: =I30/G30 -> 0.053402239 | K30: 淘宝
A31: 泡泡玛特 | B31: LABUBU | C31: 3.0 | D31: 全新 | E31: 594 | F31: 卖出 | G31: 594 | H31: 875 | I31: =H31-G31 -> 281 | J31: =I31/G31 -> 0.47306397 | K31: 小程序 | L31: 胖猪号，9月24日，整端
A32: 泡泡玛特 | B32: LABUBU | C32: 3.0 | D32: 全新 | E32: 594 | F32: 卖出 | G32: 594 | H32: 594 | I32: =H32-G32 -> 0 | J32: =I32/G32 -> 0 | K32: 小程序 | L32: 胖猪号，9月24日
A33: 泡泡玛特 | B33: LABUBU | C33: 马卡龙 | D33: 全新 | E33: 592 | F33: 卖出 | G33: 594 | H33: 1500 | I33: =H33-G33 -> 906 | J33: =I33/G33 -> 1.5252525 | K33: 小程序 | L33: 胖猪号，整端
A34: 泡泡玛特 | B34: LABUBU | C34: 3.0 | D34: 全新 | E34: 99 | F34: 留存 | K34: 盒机 | L34: 爱
A35: 泡泡玛特 | B35: LABUBU | C35: 3.0 | D35: 全新 | E35: 99 | F35: 卖出 | G35: 99 | H35: 134 | I35: =H35-G35 -> 35 | J35: =I35/G35 -> 0.35353535 | K35: 盒机 | L35: 平静
A36: 泡泡玛特 | B36: 米奇家族 | C36: 米妮 | D36: 全新 | E36: 396 | F36: 卖出 | G36: 396 | H36: 359 | I36: =H36-G36 -> -37 | J36: =I36/G36 -> -0.093434343 | K36: 盒机 | L36: 4个
A37: 泡泡玛特 | B37: 米奇家族 | C37: 米奇 | D37: 全新 | E37: 99 | F37: 留存 | K37: 盒机
A38: 泡泡玛特 | B38: 米奇家族 | C38: 高飞 | D38: 全新 | E38: 99 | F38: 留存 | K38: 盒机
A39: 泡泡玛特 | B39: 米奇家族 | C39: 布鲁托 | D39: 全新 | E39: 198 | F39: 卖出 | G39: 198 | H39: 197 | I39: =H39-G39 -> -1 | J39: =I39/G39 -> -0.0050505051 | K39: 盒机 | L39: 2个
A40: 泡泡玛特 | B40: 米奇家族 | C40: 黛西 | D40: 全新 | E40: 99 | F40: 卖出 | G40: 99 | H40: 80 | I40: =H40-G40 -> -19 | J40: =I40/G40 -> -0.19191919 | K40: 盒机
...

Sheet 并夕夕
A1: IP | B1: 系列名称 | C1: 名称 | D1: 买时状态 | E1: 状态 | F1: 总价 | G1: 成本价格 | H1: 卖出价格 | I1: 利润 | J1: 利润率 | K1: 备注
A2: 龙珠 | B2: 一番赏 | C2: 地球贝吉塔 | D2: 全新 | E2: 留存 | F2: 301 | M2: 总花销 | N2: =SUM(F:F) -> 24814
A3: 龙珠 | B3: 一番赏 | C3: 界王拳悟空 | D3: 全新 | E3: 留存 | F3: 191 | M3: 总卖出 | N3: =SUM(H:H) -> 365
A4: 龙珠 | B4: 一番赏 | C4: 肌肉特兰克斯 | D4: 全新 | E4: 留存 | F4: 351 | M4: 总卖出成本 | N4: =SUM(G:G) -> 313
A5: 龙珠 | B5: ROS | C5: 特兰克斯 | D5: 全新 | E5: 留存 | F5: 50 | M5: 利润 | N5: =SUM(I:I) -> 52
A6: 龙珠 | B6: 一番赏 | C6: 皮拉夫大王 | D6: 全新 | E6: 留存 | F6: 289 | M6: 利润率 | N6: =ROUND(N5/N4,4) -> 0.1661
A7: 龙珠 | B7: HG | C7: 比克家族 | D7: 全新 | E7: 留存 | F7: 663 | M7: 实际支出 | N7: =N2-N3 -> 24449
A8: 龙珠 | B8: 一番赏 | C8: 小沙鲁 | D8: 全新 | E8: 留存 | F8: 114
A9: 龙珠 | B9: 闪耀魅力 | C9: 比迪丽 | D9: 全新 | E9: 留存 | F9: 82 | K9: B款
A10: 龙珠 | B10: 一番赏 | C10: 桃白白 | D10: 全新 | E10: 留存 | F10: 170
A11: 龙珠 | B11: 一番赏 | C11: 小舞阿修 | D11: 全新 | E11: 留存 | F11: 359
A12: 龙珠 | B12: Grandista | C12: 悟饭 | D12: 全新 | E12: 留存 | F12: 70
A13: 龙珠 | B13: 一番赏 | C13: 比克大魔王 | D13: 全新 | E13: 留存 | F13: 161
A14: 龙珠 | B14: FES | C14: 如意棒小悟空 | D14: 全新 | E14: 留存 | F14: 69 | K14: 9
A15: 龙珠 | B15: Grandista | C15: 漫画色黑发贝吉塔 | D15: 全新 | E15: 留存 | F15: 223
A16: 龙珠 | B16: SMSP | C16: 漫画色超赛悟空 | D16: 全新 | E16: 留存 | F16: 325
A17: 龙珠 | B17: 一番赏 | C17: 机械弗利萨 | D17: 全新 | E17: 留存 | F17: 386
A18: 龙珠 | B18: Grandista | C18: 漫画色超赛贝吉塔 | D18: 全新 | E18: 留存 | F18: 250
A19: 龙珠 | B19: 一番赏 | C19: 库尔德王 | D19: 全新 | E19: 留存 | F19: 502
A20: 龙珠 | B20: 祖国 | C20: 三头胖布欧 | D20: 全新 | E20: 留存 | F20: 124 | K20: 6头，卖
A21: 龙珠 | B21: 祖国 | C21: 4形态弗利萨 | D21: 全新 | E21: 留存 | F21: 45 | K21: 卖
A22: 龙珠 | B22: Collection | C22: 琪琪 | D22: 全新 | E22: 留存 | F22: 62
A23: 龙珠 | B23: 五月人形 | C23: 盔甲小悟空 | D23: 全新 | E23: 留存 | F23: 87
A24: 鬼灭之刃 | B24: Grandista | C24: 炭治郎 | D24: 全新 | E24: 留存 | F24: 45
A25: 鬼灭之刃 | B25: Grandista | C25: 伊之助 | D25: 全新 | E25: 留存 | F25: 69
A26: 龙珠 | B26: Gxmateria | C26: 贝吉塔 | D26: 全新 | E26: 留存 | F26: 61
A27: 龙珠 | B27: Gxmateria | C27: 气功波悟饭 | D27: 全新 | E27: 留存 | F27: 56
A28: 龙珠 | B28: 历史盒子 | C28: 小悟空 | D28: 全新 | E28: 留存 | F28: 61
A29: 龙珠 | B29: 历史盒子 | C29: 巴达克 | D29: 全新 | E29: 留存 | F29: 67
A30: 龙珠 | B30: 历史盒子 | C30: 超赛悟空 | D30: 全新 | E30: 留存 | F30: 78
A31: 龙珠 | B31: SMSD | C31: 爆气悟空 | D31: 全新 | E31: 留存 | F31: 201
A32: 龙珠 | B32: Grandista | C32: 黑悟空 | D32: 全新 | E32: 留存 | F32: 100
A33: 龙珠 | B33: 闪耀魅力 | C33: 人造人18号 | D33: 全新 | E33: 留存 | F33: 227 | K33: 蓝衣白裤弯腰
A34: 龙珠 | B34: SMSP | C34: 黑发悟吉塔 | D34: 全新 | E34: 留存 | F34: 238
A35: 龙珠 | B35: BWFC | C35: 人造人17号 | D35: 全新 | E35: 留存 | F35: 92
A36: 龙珠 | B36: 闪耀魅力 | C36: 人造人18号 | D36: 全新 | E36: 留存 | F36: 82 | K36: 站姿
A37: 龙珠 | B37: 闪耀魅力 | C37: 机枪兰琪 | D37: 全新 | E37: 留存 | F37: 260 | K37: 绿色
A38: 龙珠 | B38: SMSP | C38: 超4悟空04色 | D38: 全新 | E38: 留存 | F38: 388 | K38: 蹲姿
A39: 龙珠 | B39: 燃烧的战士 | C39: 贝吉塔 | D39: 全新 | E39: 留存 | F39: 54
A40: 龙珠 | B40: Gxmateria | C40: 踩波悟空 | D40: 全新 | E40: 留存 | F40: 66
...

Sheet 预定
A1: IP | B1: 系列名称 | C1: 名称 | D1: 定金 | E1: 尾款 | F1: 运费 | G1: 状态 | H1: 总价 | I1: 卖出成本 | J1: 卖出价格 | K1: 利润 | L1: 利润率 | M1: 途径 | N1: 备注
A2: 龙珠 | B2: BOS | C2: 超3悟天克斯 | D2: 10 | G2: 卖出 | H2: =D2+E2+F2 -> 10 | I2: 10 | J2: 0 | K2: =J2-I2 -> -10 | L2: =ROUND(K2/I2,4) -> -1 | M2: 淘宝一诺 | N2: 弃单 | P2: 总花销 | Q2: =SUM(H:H) -> 96642
A3: 龙珠 | B3: HG | C3: 人造人 | D3: 81 | E3: 668 | G3: 留存 | H3: =D3+E3+F3 -> 749 | M3: 指乐无穷 | N3: 24年2月 | P3: 总卖出 | Q3: =SUM(J:J) -> 19270
A4: 海贼王 | B4: 桌面系列 | C4: 路飞全形态 | D4: 34 | E4: 409 | G4: 留存 | H4: =D4+E4+F4 -> 443 | M4: 指乐无穷 | N4: 24年3月，一坨 | P4: 总卖出成本 | Q4: =SUM(I:I) -> 18628
A5: 龙珠 | B5: PLEX | C5: 变身萨博 | D5: 333 | E5: 1428 | G5: 卖出 | H5: =D5+E5+F5 -> 1761 | I5: 1761 | J5: 1846 | K5: =J5-I5 -> 85 | L5: =ROUND(K5/I5,4) -> 0.0483 | M5: 指乐无穷 | N5: 24年2月 | P5: 利润 | Q5: =SUM(K:K) -> 642
A6: 龙珠 | B6: PLEX | C6: 萨博 | D6: 284 | E6: 1415 | F6: 16 | G6: 留存 | H6: =D6+E6+F6 -> 1715 | M6: 淘宝华宝 | N6: 24年1月 | P6: 利润率 | Q6: =ROUND(Q5/Q4,4) -> 0.0345
A7: 龙珠 | B7: PLEX | C7: 多多利亚 | D7: 299 | E7: 1395 | G7: 卖出 | H7: =D7+E7+F7 -> 1694 | I7: 1694 | J7: 1760 | K7: =J7-I7 -> 66 | L7: =ROUND(K7/I7,4) -> 0.039 | M7: 指乐无穷 | N7: 24年4月 | P7: 实际支出 | Q7: =Q2-Q3 -> 77372
A8: 龙珠 | B8: SHF | C8: 9号胶囊机车 | D8: 46 | E8: 410 | G8: 留存 | H8: =D8+E8+F8 -> 456 | M8: 指乐无穷 | N8: 24年4月
A9: 龙珠 | B9: PLEX | C9: 多多利亚 | D9: 295 | E9: 1438 | G9: 留存 | H9: =D9+E9+F9 -> 1733 | M9: 淘宝华宝 | N9: 24年4月
A10: 龙珠 | B10: 出阵 | C10: 基纽特战队 | D10: 76 | E10: 360 | G10: 留存 | H10: =D10+E10+F10 -> 436 | M10: 塑唐 | N10: 24年7月
A11: 啦啦队系列 | B11: Hobby·sakura | C11: 美沙纪 | D11: 70 | E11: 504 | G11: 卖出 | H11: =D11+E11+F11 -> 574 | I11: 574 | J11: 520 | K11: =J11-I11 -> -54 | L11: =ROUND(K11/I11,4) -> -0.0941 | M11: 咸鱼 | N11: 24年7月
A12: 啦啦队系列 | B12: Hobby·sakura | C12: 美沙纪 | D12: 192 | E12: 436 | G12: 留存 | H12: =D12+E12+F12 -> 628 | N12: 24年7月
A13: 龙珠 | C13: 鸟山明玩大便 | D13: 450 | E13: 0 | F13: 18 | G13: 留存 | H13: =D13+E13+F13 -> 468 | M13: 咸鱼 | N13: 手艺人自制
A14: 街霸 | B14: Max Factory | C14: 春丽 | D14: 245 | E14: 1700 | F14: 18 | G14: 留存 | H14: =D14+E14+F14 -> 1963 | M14: 模玩熊 | N14: 24年7月
A15: 龙珠 | B15: 桌面系列 | C15: 父子机车 | D15: 46 | E15: 1250 | G15: 留存 | H15: =D15+E15+F15 -> 1296 | M15: 塑唐
A16: 遗孀之雪女 | B16: PURE | C16: 雪乃深冬 | D16: 248 | E16: 650 | G16: 留存 | H16: =D16+E16+F16 -> 898 | M16: Hobby Heaven | N16: 24年9月
A17: 间谍过家家 | B17: GK | C17: 婴儿车阿尼亚 | D17: 173 | E17: 290 | G17: 卖出 | H17: =D17+E17+F17 -> 463 | I17: 463 | J17: 437 | K17: =J17-I17 -> -26 | L17: =ROUND(K17/I17,4) -> -0.0562 | M17: 淘宝 | N17: 24年3季度末
A18: CW | B18: Vibrastar | C18: 修女 | D18: 150 | E18: 904 | G18: 卖出 | H18: =D18+E18+F18 -> 1054 | I18: 1054 | J18: 1053 | K18: =J18-I18 -> -1 | L18: =ROUND(K18/I18,4) -> -0.0009 | M18: 橘子屋 | N18: 24年10月
A19: 东方Project | B19: APEX-TOYS | C19: 蕾米莉亚 | D19: 146 | E19: 967 | G19: 留存 | H19: =D19+E19+F19 -> 1113 | M19: 淘宝叔叔 | N19: 24年10月
A20: 啦啦队系列 | B20: Hobby·sakura | C20: 莉库 | D20: 123 | E20: 488 | G20: 留存 | H20: =D20+E20+F20 -> 611 | M20: 淘宝叔叔 | N20: 24年11月
A21: 原创 | B21: Hobby·sakura | C21: 不良女警 | D21: 107 | E21: 691 | G21: 留存 | H21: =D21+E21+F21 -> 798 | M21: 淘宝叔叔 | N21: 24年11月，卖
A22: 神明渴望游戏。 | B22: elCOCO | C22: 帕尔 | D22: 30 | E22: 131 | G22: 留存 | H22: =D22+E22+F22 -> 161 | M22: 指乐无穷 | N22: 24年11月，卖
A23: 沙漠大冒险 | B23: 桌面系列 | C23: 104战车 | D23: 278 | E23: 1217 | G23: 留存 | H23: =D23+E23+F23 -> 1495 | M23: 指乐无穷 | N23: 24年11月
A24: 无职转生 | B24: Mega House | C24: 艾莉丝 | D24: 40 | E24: 383 | G24: 留存 | H24: =D24+E24+F24 -> 423 | M24: 淘宝叔叔 | N24: 24年11月
A25: 无职转生 | B25: 寿屋 | C25: 艾莉丝 | D25: 106 | E25: 591 | G25: 留存 | H25: =D25+E25+F25 -> 697 | M25: 叔叔会员购 | N25: 24年12月
A26: 无职转生 | B26: 寿屋 | C26: 艾莉丝 | D26: 60 | E26: 566 | G26: 卖出 | H26: =D26+E26+F26 -> 626 | I26: 626 | J26: 538 | K26: =J26-I26 -> -88 | L26: =ROUND(K26/I26,4) -> -0.1406 | M26: 淘宝叔叔 | N26: 25年1月
A27: 更衣人偶坠入爱河 | B27: Taito | C27: 喜多川海梦 利兹 | D27: 22 | E27: 65 | F27: 8 | G27: 留存 | H27: =D27+E27+F27 -> 95 | M27: 淘宝Hpoi | N27: 24年12月
A28: 龙珠 | B28: FiguartsZERO | C28: 超级赛亚人2孙悟饭-汹涌的实力 | D28: 103 | E28: 474 | G28: 留存 | H28: =D28+E28+F28 -> 577 | M28: 叔叔会员购 | N28: 24年12月
A29: 青春恋爱物语 | B29: GSC | C29: 雪乃 | D29: 121 | E29: 665 | G29: 留存 | H29: =D29+E29+F29 -> 786 | M29: 淘宝叔叔 | N29: 24年12月
A30: SIKI ANIM | C30: 阿尔维娜 | D30: 50 | E30: 248 | G30: 留存 | H30: =D30+E30+F30 -> 298 | M30: 淘宝Hpoi | N30: 25年1月，卖
A31: 龙珠 | B31: HG | C31: 皮拉夫三人组 | D31: 130 | E31: 581 | G31: 留存 | H31: =D31+E31+F31 -> 711 | M31: 指乐无穷 | N31: 25年2月
A32: 东方Project | B32: MAGI ARTS | C32: 十六夜咲夜 | D32: 165 | E32: 822 | G32: 留存 | H32: =D32+E32+F32 -> 987 | M32: 叔叔会员购 | N32: 25年2月，卖
A33: 魔女之旅 | B33: Taito | C33: 伊蕾娜 | D33: 22 | E33: 75 | G33: 留存 | H33: =D33+E33+F33 -> 97 | M33: 淘宝Hpoi | N33: 25年3月
A34: 黑岩射手 | B34: GSC | C34: 狂化黑岩射手 | D34: 99 | E34: 747 | G34: 留存 | H34: =D34+E34+F34 -> 846 | M34: GSC小程序 | N34: 25年3月
A35: 黑岩射手 | B35: GSC | C35: 狂化黑岩射手 | D35: 90 | E35: 747 | G35: 卖出 | H35: =D35+E35+F35 -> 837 | I35: 837 | J35: 777 | K35: =J35-I35 -> -60 | L35: =ROUND(K35/I35,4) -> -0.0717 | M35: GSC小程序 | N35: 25年3月
A36: 黑岩射手 | B36: GSC | C36: 狂化黑岩射手 | D36: 100 | E36: 747 | G36: 留存 | H36: =D36+E36+F36 -> 847 | M36: GSC小程序 | N36: 25年3月，卖
B37: OMAHA | C37: 波妮塔酱 | D37: 200 | E37: 696 | G37: 留存 | H37: =D37+E37+F37 -> 896 | M37: 淘宝橘子屋 | N37: 25年4月
A38: 龙珠 | B38: 桌面系列 | C38: 超赛父子机车 | D38: 94 | E38: 1085 | G38: 留存 | H38: =D38+E38+F38 -> 1179 | M38: 塑唐 | N38: 25年4月
A39: 命运石之门 | B39: WAVE | C39: 牧濑红莉栖 | D39: 120 | E39: 522 | G39: 卖出 | H39: =D39+E39+F39 -> 642 | I39: 642 | J39: 764 | K39: =J39-I39 -> 122 | L39: =ROUND(K39/I39,4) -> 0.19 | M39: 淘宝Hpoi | N39: 25年4月
A40: 约会大作战 | B40: Taito | C40: 时崎狂三 | D40: 22 | E40: 72 | G40: 留存 | H40: =D40+E40+F40 -> 94 | M40: 淘宝Hpoi | N40: 25年4月
...

Sheet 抖音
A1: IP | B1: 系列名称 | C1: 名称 | D1: 买时状态 | E1: 状态 | F1: 总价 | G1: 卖出成本 | H1: 卖出价格 | I1: 利润 | J1: 利润率 | K1: 备注
A2: 龙珠 | B2: BWFC | C2: 蓝发悟吉塔01色 | D2: 全新 | E2: 留存 | F2: 115 | M2: 总花销 | N2: =SUM(F:F) -> 10862
A3: 龙珠 | B3: Gxmateria | C3: 龟仙人 | D3: 全新 | E3: 留存 | F3: 45 | M3: 总卖出 | N3: =SUM(H:H) -> 8461
A4: 龙珠 | B4: Gxmateria | C4: 巴达克 | D4: 全新 | E4: 卖出 | F4: 44 | G4: 44 | H4: 51 | I4: =H4-G4 -> 7 | J4: =I4/G4 -> 0.15909091 | M4: 总卖出成本 | N4: =SUM(G:G) -> 7626
A5: 龙珠 | B5: Gxmateria | C5: 踩波悟空 | D5: 全新 | E5: 卖出 | F5: 37 | G5: 37 | H5: 53 | I5: =H5-G5 -> 16 | J5: =I5/G5 -> 0.43243243 | M5: 利润 | N5: =SUM(I:I) -> 835
A6: 龙珠 | B6: HG | C6: 布欧全形态 | D6: 全新 | E6: 卖出 | F6: 399 | G6: 399 | H6: 415 | I6: =H6-G6 -> 16 | J6: =I6/G6 -> 0.040100251 | M6: 利润率 | N6: =ROUND(N5/N4,4) -> 0.1095
A7: 鬼灭之刃 | B7: WCF | C7: 主公大人面前 | D7: 全新 | E7: 留存 | F7: 147 | M7: 实际支出 | N7: =N2-N3 -> 2401
A8: 鬼灭之刃 | B8: WCF | C8: 炭治郎 | D8: 全新 | E8: 留存 | F8: 149
A9: 美少女战士 | B9: 闪耀魅力 | C9: 水兵月 | D9: 全新 | E9: 留存 | F9: 59 | K9: 已拆
A10: 奥特曼 | B10: SHF | C10: 特利伽奥特曼 | D10: 全新 | E10: 卖出 | F10: 124 | G10: 124 | H10: 139 | I10: =H10-G10 -> 15 | J10: =I10/G10 -> 0.12096774
A11: 奥特曼 | B11: SHF | C11: 特利伽奥特曼 | D11: 全新 | E11: 卖出 | F11: 130 | G11: 130 | H11: 143 | I11: =H11-G11 -> 13 | J11: =I11/G11 -> 0.1
A12: 奥特曼 | B12: SHF | C12: 特利伽奥特曼 | D12: 全新 | E12: 卖出 | F12: 130 | G12: 130 | H12: 157 | I12: =H12-G12 -> 27 | J12: =I12/G12 -> 0.20769231
A13: 奥特曼 | B13: SHF | C13: 特利伽奥特曼 | D13: 全新 | E13: 卖出 | F13: 130 | G13: 130 | H13: 170 | I13: =H13-G13 -> 40 | J13: =I13/G13 -> 0.30769231
A14: 奥特曼 | B14: SHF | C14: 特利伽奥特曼 | D14: 全新 | E14: 卖出 | F14: 130 | G14: 130 | H14: 169 | I14: =H14-G14 -> 39 | J14: =I14/G14 -> 0.3
A15: 奥特曼 | B15: SHF | C15: 特利伽奥特曼 | D15: 全新 | E15: 卖出 | F15: 130 | G15: 130 | H15: 179 | I15: =H15-G15 -> 49 | J15: =I15/G15 -> 0.37692308
A16: 怪物猎人 | B16: SHM | C16: 雄火龙 | D16: 全新 | E16: 卖出 | F16: 500 | G16: 500 | H16: 557 | I16: =H16-G16 -> 57 | J16: =I16/G16 -> 0.114
A17: 火影忍者 | B17: SHF | C17: 鸣人 | D17: 全新 | E17: 卖出 | F17: 110 | G17: 110 | H17: 128 | I17: =H17-G17 -> 18 | J17: =I17/G17 -> 0.16363636
A18: 胜利女神：新的希望 | B18: S.K.P | C18: 桃乐丝 | D18: 全新 | E18: 卖出 | F18: 238 | G18: 238 | H18: 417 | I18: =H18-G18 -> 179 | J18: =I18/G18 -> 0.75210084
A19: 星光咖啡馆与死神之蝶 | B19: Alice Glint | C19: 四季夏目 旗袍 | D19: 全新 | E19: 卖出 | F19: 1396 | G19: 1396 | H19: 1460 | I19: =H19-G19 -> 64 | J19: =I19/G19 -> 0.045845272
A20: 星光咖啡馆与死神之蝶 | B20: Alice Glint | C20: 四季夏目 旗袍 | D20: 全新 | E20: 卖出 | F20: 1396 | G20: 1396 | H20: 1441 | I20: =H20-G20 -> 45 | J20: =I20/G20 -> 0.032234957
A21: 星光咖啡馆与死神之蝶 | B21: Alice Glint | C21: 四季夏目 旗袍 | D21: 全新 | E21: 卖出 | F21: 1400 | G21: 1400 | H21: 1471 | I21: =H21-G21 -> 71 | J21: =I21/G21 -> 0.050714286 | K21: 老于抖音
A22: 星光咖啡馆与死神之蝶 | B22: Alice Glint | C22: 四季夏目 旗袍 | D22: 全新 | E22: 卖出 | F22: 1332 | G22: 1332 | H22: 1511 | I22: =H22-G22 -> 179 | J22: =I22/G22 -> 0.13438438
A23: 星光咖啡馆与死神之蝶 | B23: Alice Glint | C23: 四季夏目 旗袍 | D23: 全新 | E23: 留存 | F23: 1427
A24: 星光咖啡馆与死神之蝶 | B24: Alice Glint | C24: 四季夏目 旗袍 | D24: 全新 | E24: 留存 | F24: 1294

Sheet 套书+单行本
A1: IP | B1: 种类 | C1: 出版社 | D1: 版本 | E1: 册数 | F1: 尺寸 | G1: 完结度 | H1: 作者 | I1: 买时状态 | J1: 首刷 | K1: 盒装 | L1: 状态 | M1: 总价 | N1: 返利 | O1: 实际价格 | P1: 卖出成本 | Q1: 卖出价格 | R1: 利润 | S1: 利润率 | T1: 渠道
A2: 龙珠 | B2: 漫画 | C2: 东立 | D2: 完全版 | E2: 34 | F2: 25K | G2: 完结 | H2: 鸟山明 | I2: 全新 | L2: 留存 | M2: 1939 | T2: 淘宝 | V2: 总花销 | W2: =SUM(M:M) -> 55327
A3: 龙珠 | B3: 漫画 | C3: 集英社 | D3: 40周年日版 | E3: 42 | F3: 36K | G3: 完结 | H3: 鸟山明 | I3: 全新 | L3: 留存 | M3: 1001 | T3: 京东 | V3: 总卖出 | W3: =SUM(Q:Q) -> 726
A4: 阿拉蕾 | B4: 漫画 | C4: 东立 | D4: 完全版 | E4: 15 | F4: 25K | G4: 完结 | H4: 鸟山明 | I4: 全新 | L4: 留存 | M4: 895 | T4: 京东 | V4: 总卖出成本 | W4: =SUM(P:P) -> 721
A5: 沙漠大冒险 | B5: 漫画 | C5: 四川美术 | D5: 简中 | E5: 1 | F5: 32K | G5: 完结 | H5: 鸟山明 | I5: 全新 | L5: 留存 | M5: 3 | T5: 京东 | V5: 利润 | W5: =SUM(R:R) -> 5
A6: 银河巡警加克 | B6: 漫画 | C6: 东立 | D6: 台版 | E6: 1 | F6: 36K | G6: 完结 | H6: 鸟山明 | I6: 全新 | L6: 留存 | M6: 12 | T6: 抖音 | V6: 利润率 | W6: =ROUND(W5/W4,4) -> 0.0069
A7: 桂＆明 桂正和✕鸟山明共同短篇集 | B7: 漫画 | C7: 东立 | D7: 台版 | E7: 1 | F7: 32K | G7: 完结 | H7: 鸟山明 | I7: 全新 | L7: 留存 | M7: 0 | T7: 抖音 | V7: 实际支出 | W7: =W2-W3 -> 54601
A8: 亚人 | B8: 漫画 | C8: 东立 | D8: 台版 | E8: 17 | F8: 32K | G8: 完结 | H8: 樱井画门 | I8: 全新 | L8: 留存 | M8: 520 | T8: 抖音
A9: 行星POOL | B9: 漫画 | C9: 东立 | D9: 台版 | E9: 1 | F9: 32K | G9: 完结 | H9: 樱井画门 | I9: 全新 | J9: 首限 | L9: 留存 | M9: 32 | T9: 抖音
A10: 异兽魔都 | B10: 漫画 | C10: 长鸿 | D10: 典藏版 | E10: 23 | F10: 32K | G10: 完结 | H10: 林田球 | I10: 全新 | L10: 留存 | M10: 1058 | T10: 博客来
A11: 鬼灭之刃 | B11: 漫画 | C11: 东立 | D11: 台版 | E11: 23 | F11: 36K | G11: 完结 | H11: 吾峠呼世晴 | I11: 全新 | L11: 留存 | M11: 404 | T11: 京东
A12: 幽游白书 | B12: 漫画 | C12: 中信 | D12: 简中 | F12: 25K | G12: 完结 | H12: 富㭴义博 | I12: 全新 | L12: 留存 | M12: 131 | T12: 拼多多，出
A13: 幽游白书 | B13: 漫画 | C13: 东立 | D13: 完全版 | E13: 15 | F13: 25K | G13: 完结 | H13: 富㭴义博 | I13: 全新 | L13: 留存 | M13: 664 | T13: 京东
A14: 伊藤润二 | B14: 漫画 | C14: 东立 | D14: 爱藏版 | E14: 11 | F14: 32K | G14: 完结 | H14: 伊藤润二 | I14: 全新 | L14: 留存 | M14: 639 | T14: 博客来
A15: 伊藤润二 4 至死不渝的爱 | B15: 漫画 | C15: 东立 | D15: 爱藏版 | E15: 1 | F15: 32K | G15: 完结 | H15: 伊藤润二 | I15: 拆摆 | L15: 留存 | M15: 20 | T15: 抖音
A16: 旋涡 | B16: 漫画 | C16: 小学馆 | D16: 日版 | E16: 1 | F16: 32K | G16: 完结 | H16: 伊藤润二 | I16: 全新 | L16: 留存 | M16: 65 | T16: 日本带回
A17: 伊藤润二展 诱惑 Illustrations | B17: 画集 | C17: 朝日新闻 | D17: 日版 | E17: 1 | F17: 16K | G17: 完结 | H17: 伊藤润二 | I17: 全新 | L17: 留存 | M17: 176 | T17: 日本带回
A18: 伊藤润二展 诱惑 Illustrations | B18: 画集 | C18: 东立 | D18: 台版 | E18: 1 | F18: 16K | G18: 完结 | H18: 伊藤润二 | I18: 全新 | L18: 留存 | M18: 134 | T18: 抖音
A19: 禁入空间 | B19: 漫画 | C19: 东立 | D19: 台版 | E19: 1 | F19: 25K | G19: 完结 | H19: 伊藤润二 | I19: 全新 | L19: 留存 | M19: 69 | T19: 抖音
A20: 幻怪地带 | B20: 漫画 | C20: 东立 | D20: 台版 | E20: 1 | F20: 25K | G20: 完结 | H20: 伊藤润二 | I20: 全新 | L20: 留存 | M20: 55 | T20: 抖音
A21: 幻怪地带 以太村 | B21: 漫画 | C21: 东立 | D21: 台版 | E21: 1 | F21: 25K | G21: 完结 | H21: 伊藤润二 | I21: 全新 | L21: 留存 | M21: 55 | T21: 抖音
A22: 感应 | B22: 漫画 | C22: 东立 | D22: 台版 | E22: 1 | F22: 32K | G22: 完结 | H22: 伊藤润二 | I22: 全新 | L22: 留存 | M22: 46 | T22: 抖音
A23: 地狱星 | B23: 漫画 | C23: 东立 | D23: 台版 | E23: 1 | F23: 32K | G23: 完结 | H23: 伊藤润二 | I23: 全新 | L23: 留存 | M23: 41 | T23: 抖音
A24: 黑色诡局 | B24: 漫画 | C24: 东立 | D24: 台版 | E24: 1 | F24: 36K | G24: 完结 | H24: 伊藤润二 | I24: 全新 | L24: 留存 | M24: 41 | T24: 抖音
... A38: 守护甜心 5 | B38: 漫画 | C38: 长鸿 | D38: 爱藏版 | E38: 1 | F38: 25K | G38: 完结 | H38: 江原涉子 | I38: 全新 | L38: 留存 | M38: 32 | T38: 抖音
A39: 守护甜心 6 | B39: 漫画 | C39: 长鸿 | D39: 爱藏版 | E39: 1 | F39: 25K | G39: 完结 | H39: 江原涉子 | I39: 全新 | L39: 留存 | T39: 抖音
A40: 浪客行 | B40: 漫画 | C40: 尖端 | D40: 台版 | E40: 37 | F40: 32K | G40: 完结 | H40: 井上雄彦 | I40: 全新 | L40: 留存 | M40: 963 | T40: 京东
A41: SLAM DUNK 灌篮高手总集篇 | B41: 漫画 | C41: 尖端 | D41: 台版 | E41: 1 | F41: 16K | G41: 完结 | H41: 井上雄彦 | I41: 全新 | L41: 留存 | M41: 25 | T41: 抖音
A42: 纯真之人 | B42: 漫画 | C42: 尖端 | D42: 台版 | E42: 9 | F42: 32K | G42: 完结 | H42: 坂本真一 | I42: 全新 | L42: 留存 | M42: 265 | T42: 抖音
A43: 灵能百分百+番外 | B43: 漫画 | C43: 湖南文艺 | D43: 简中 | E43: 17 | F43: 32K | G43: 完结 | H43: ONE | I43: 全新 | L43: 留存 | M43: 126 | T43: 淘宝
A44: 电锯人 最佳拍档 | B44: 轻小说 | E44: 1 | F44: 32K | G44: 完结 | H44: 藤本树 | I44: 全新 | L44: 留存 | M44: 17 | T44: 淘宝
A45: 蓦然回首 再见绘梨 | B45: 漫画 | E45: 2 | F45: 32K | G45: 完结 | H45: 藤本树 | I45: 全新 | L45: 留存 | M45: 18 | T45: 淘宝
A46: 炎拳 | B46: 漫画 | C46: 东立 | D46: 台版 | E46: 8 | F46: 36K | G46: 完结 | H46: 藤本树 | I46: 全新 | L46: 留存 | M46: 130 | T46: 淘宝
A47: 17-21 22-26 | B47: 漫画 | E47: 2 | F47: 32K | G47: 完结 | H47: 藤本树 | I47: 全新 | L47: 留存 | M47: 22 | T47: 淘宝
A48: 美少女战士 | B48: 漫画 | C48: 青文 | D48: 完全版 | E48: 10 | F48: 25K | G48: 完结 | H48: 武内直子 | I48: 全新 | L48: 留存 | M48: 713 | T48: 京东
A49: 关于地球的运动 1-4 | B49: 漫画 | C49: 九州 | D49: 简中 | E49: 4 | F49: 32K | G49: 完结 | H49: 鱼丰 | I49: 全新 | L49: 留存 | M49: 48 | T49: 京东
A50: 关于地球的运动 5-8 | B50: 漫画 | C50: 九州 | D50: 简中 | E50: 4 | F50: 32K | G50: 完结 | H50: 鱼丰 | I50: 全新 | L50: 留存 | M50: 31 | T50: 京东
A51: 夏日重现 | B51: 漫画 | C51: 东立 | D51: 台版 | E51: 13 | F51: 36K | G51: 完结 | H51: 田中靖规 | I51: 全新 | L51: 留存 | M51: 264 | T51: 小红书 胖猪号
A52: H2 | B52: 漫画 | C52: 青文 | D52: 典藏版 | E52: 17 | F52: 32K | G52: 完结 | H52: 安达充 | I52: 全新 | L52: 留存 | M52: 583 | T52: 小红书 杨树林
A53: 青春方程式 | B53: 漫画 | C53: 新星 | D53: 简中 | E53: 3 | F53: 32K | G53: 完结 | H53: 安达充 | I53: 全新 | L53: 留存 | M53: 34 | T53: 京东
...

Sheet 散本+未完结
A1: IP | B1: 种类 | C1: 出版社 | D1: 版本 | E1: 册数 | F1: 尺寸 | G1: 完结度 | H1: 作者 | I1: 买时状态 | J1: 首刷 | K1: 盒装 | L1: 状态 | M1: 总价 | N1: 卖出成本 | O1: 卖出价格 | P1: 利润 | Q1: 利润率 | R1: 渠道
A2: 龙珠 超全集 1 | B2: 公式书 | C2: 香港文化传信 | D2: 港版 | E2: 1 | F2: 16K | G2: 完结 | H2: 鸟山明 | I2: 全新 | L2: 留存 | M2: 158 | R2: 抖音 卖 | T2: 总花销 | U2: =SUM(M:M) -> 20435
A3: 龙珠 超全集 1 | B3: 公式书 | C3: 香港文化传信 | D3: 港版 | E3: 1 | F3: 16K | G3: 完结 | H3: 鸟山明 | I3: 全新 | L3: 留存 | M3: 135 | R3: 抖音 | T3: 总卖出 | U3: =SUM(O:O) -> 0
A4: 龙珠 超全集 2 | B4: 公式书 | C4: 香港文化传信 | D4: 港版 | E4: 1 | F4: 16K | G4: 完结 | H4: 鸟山明 | I4: 全新 | L4: 留存 | M4: 158 | R4: 抖音 | T4: 总卖出成本 | U4: =SUM(N:N) -> 0
A5: 龙珠 超全集 3 | B5: 公式书 | C5: 香港文化传信 | D5: 港版 | E5: 1 | F5: 16K | G5: 完结 | H5: 鸟山明 | I5: 全新 | L5: 留存 | R5: 抖音 | T5: 利润 | U5: =SUM(P:P) -> 0
A6: 龙珠 超全集 4 | B6: 公式书 | C6: 香港文化传信 | D6: 港版 | E6: 1 | F6: 16K | G6: 完结 | H6: 鸟山明 | I6: 全新 | L6: 留存 | T6: 利润率 | U6: =ROUND(U5/U4,4) -> #DIV/0!
A7: 大黑暗 1-7 | B7: 漫画 | C7: 东立 | D7: 台版 | E7: 7 | F7: 32K | G7: 连载中 | H7: 林田球 | I7: 全新 | L7: 留存 | M7: 331 | R7: 淘宝 | T7: 实际支出 | U7: =U2-U3 -> 20435
A8: 大黑暗 8 | B8: 漫画 | C8: 东立 | D8: 台版 | E8: 1 | F8: 32K | G8: 连载中 | H8: 林田球 | I8: 全新 | L8: 留存 | R8: 小红书
A9: 败犬女主 1-7+SSS | B9: 轻小说 | C9: 东立 | D9: 台版 | E9: 8 | F9: 32K | G9: 连载中 | H9: 雨森焚火 | I9: 全新 | L9: 留存 | M9: 278 | R9: 京东
A10: 败犬女主 8 | B10: 轻小说 | C10: 东立 | D10: 台版 | E10: 1 | F10: 32K | G10: 连载中 | H10: 雨森焚火 | I10: 全新 | L10: 留存 | M10: 29 | R10: 京东
A11: 败犬女主 8.5 | B11: 轻小说 | C11: 东立 | D11: 台版 | E11: 1 | F11: 32K | G11: 连载中 | H11: 雨森焚火 | I11: 全新 | J11: 首限 | L11: 留存 | M11: 99 | R11: 抖音
A12: 全职猎人 | B12: 漫画 | C12: 东立 | D12: 台版 | E12: 38 | F12: 36K | G12: 连载中 | H12: 富㭴义博 | I12: 全新 | L12: 留存 | M12: 535 | R12: 淘宝
A13: 孤高之人 1-12 | B13: 漫画 | C13: 尖端 | D13: 台版 | E13: 12 | F13: 32K | G13: 连载中 | H13: 坂本真一 | I13: 全新 | L13: 留存 | M13: 254 | R13: 京东
A14: 孤高之人 13 | B14: 漫画 | C14: 尖端 | D14: 台版 | E14: 1 | F14: 32K | G14: 连载中 | H14: 坂本真一 | I14: 全新 | L14: 留存 | M14: 20 | R14: 抖音
A15: 孤高之人 14 | B15: 漫画 | C15: 尖端 | D15: 台版 | E15: 1 | F15: 32K | G15: 连载中 | H15: 坂本真一 | I15: 全新 | L15: 留存 | M15: 21 | R15: 博客来
A16: 孤高之人 15 | B16: 漫画 | C16: 尖端 | D16: 台版 | E16: 1 | F16: 32K | G16: 连载中 | H16: 坂本真一 | I16: 全新 | L16: 留存
A17: 孤高之人 16 | B17: 漫画 | C17: 尖端 | D17: 台版 | E17: 1 | F17: 32K | G17: 连载中 | H17: 坂本真一 | I17: 全新 | L17: 留存
A18: 孤高之人 17 | B18: 漫画 | C18: 尖端 | D18: 台版 | E18: 1 | F18: 32K | G18: 连载中 | H18: 坂本真一 | I18: 全新 | L18: 留存
A19: 纯真之人 Rough 1-6 | B19: 漫画 | C19: 尖端 | D19: 台版 | E19: 6 | F19: 32K | G19: 连载中 | H19: 坂本真一 | I19: 全新 | L19: 留存 | M19: 211 | R19: 抖音
A20: 隐藏技能 BUG EGO 1 | B20: 漫画 | C20: 东立 | D20: 台版 | E20: 1 | F20: 32K | G20: 连载中 | H20: ONE | I20: 全新 | L20: 留存 | M20: 19 | R20: 抖音
A21: 隐藏技能 BUG EGO 2 | B21: 漫画 | C21: 东立 | D21: 台版 | E21: 1 | F21: 32K | G21: 连载中 | H21: ONE | I21: 全新 | L21: 留存 | M21: 14 | R21: 抖音
A22: 隐藏技能 BUG EGO 3 | B22: 漫画 | C22: 东立 | D22: 台版 | E22: 1 | F22: 32K | G22: 连载中 | H22: ONE | I22: 全新 | J22: 首限 | L22: 留存 | M22: 35 | R22: 抖音
A23: 伪恋 14 | B23: 漫画 | C23: 东立 | D23: 爱藏版 | E23: 1 | F23: 32K | G23: 连载中 | H23: 古味直志 | I23: 全新 | L23: 留存 | R23: 会员购
A24: 天使心1st 1-8 | B24: 漫画 | C24: 尖端 | D24: 典藏版 | E24: 8 | F24: 25K | G24: 完结 | H24: 北条司 | I24: 全新 | K24: 盒装 | L24: 留存 | M24: 202 | R24: 淘宝 瑕疵版
A25: 天使心1st 9-16 | B25: 漫画 | C25: 尖端 | D25: 典藏版 | E25: 8 | F25: 25K | G25: 完结 | H25: 北条司 | I25: 全新 | K25: 盒装 | L25: 留存 | M25: 445 | R25: 抖音
A26: 天使心1st 17-24 | B26: 漫画 | C26: 尖端 | D26: 典藏版 | E26: 8 | F26: 25K | G26: 完结 | H26: 北条司 | I26: 全新 | K26: 盒装 | L26: 留存 | M26: 416 | R26: 京东
A27: 天使心2nd 1-8 | B27: 漫画 | C27: 尖端 | D27: 典藏版 | E27: 8 | F27: 25K | G27: 完结 | H27: 北条司 | I27: 全新 | K27: 盒装 | L27: 留存 | M27: 319 | R27: 淘宝
A28: 天使心2nd 9-16 | B28: 漫画 | C28: 尖端 | D28: 典藏版 | E28: 8 | F28: 25K | G28: 完结 | H28: 北条司 | I28: 全新 | K28: 盒装 | L28: 留存 | M28: 365 | R28: 京东
A29: 城市猎人17-24 | B29: 漫画 | C29: 尖端 | D29: 完全版 | E29: 8 | F29: 25K | G29: 完结 | H29: 北条司 | I29: 拆摆 | L29: 留存 | M29: 350 | R29: 抖音 瑕疵版
A30: 城市猎人25-32 | B30: 漫画 | C30: 尖端 | D30: 完全版 | E30: 8 | F30: 25K | G30: 完结 | H30: 北条司 | I30: 拆摆 | L30: 留存 | M30: 297 | R30: 抖音 瑕疵版
A31: 北条司短篇集（三本） | B31: 漫画 | C31: 玉皇朝 | D31: 珍藏版 | E31: 3 | F31: 32K | G31: 完结 | H31: 北条司 | I31: 全新 | L31: 留存 | M31: 167 | R31: 抖音 《艳阳少女》，《RASH!! 辣妹狱医》
A32: 危险调查员 1-4 | B32: 漫画 | C32: 尖端 | D32: 完全版 | E32: 4 | F32: 25K | G32: 完结 | H32: 浦泽直树 | I32: 全新 | K32: 盒装 | L32: 留存 | M32: 222 | R32: 抖音
A33: 危险调查员 5-8 | B33: 漫画 | C33: 尖端 | D33: 完全版 | E33: 4 | F33: 25K | G33: 完结 | H33: 浦泽直树 | I33: 全新 | K33: 盒装 | L33: 留存 | M33: 224 | R33: 抖音
A34: 危险调查员 9-12 | B34: 漫画 | C34: 尖端 | D34: 完全版 | E34: 4 | F34: 25K | G34: 完结 | H34: 浦泽直树 | I34: 全新 | K34: 盒装 | L34: 留存 | R34: 京东
A35: 侦探学园Q 1 | B35: 漫画 | C35: 东立 | D35: 爱藏版 | E35: 1 | F35: 32K | G35: 连载中 | H35: 天树征丸 | I35: 全新 | J35: 首限 | L35: 留存 | R35: 抖音
A36: 侦探学园Q 2 | B36: 漫画 | C36: 东立 | D36: 爱藏版 | E36: 1 | F36: 32K | G36: 连载中 | H36: 天树征丸 | I36: 全新 | J36: 首限 | L36: 留存 | R36: 抖音
A37: 侦探学园Q 3 | B37: 漫画 | C37: 东立 | D37: 爱藏版 | E37: 1 | F37: 32K | G37: 连载中 | H37: 天树征丸 | I37: 全新 | J37: 首限 | L37: 留存 | M37: 32 | R37: 抖音
A38: 眨眼之声 1 | B38: 漫画 | C38: 东立 | D38: 台版 | E38: 1 | F38: 32K | G38: 连载中 | H38: 押见修造 | I38: 全新 | L38: 留存 | M38: 42 | R38: 抖音
A39: 魔都精兵的奴隶 1-19 | B39: 漫画 | C39: 东立 | D39: 台版 | E39: 19 | F39: 32K | G39: 连载中 | H39: タカヒロ | I39: 全新 | L39: 留存 | M39: 750 | R39: 闲鱼
A40: 魔都精兵的奴隶 20 | B40: 漫画 | C40: 东立 | D40: 台版 | E40: 1 | F40: 32K | G40: 连载中 | H40: タカヒロ | I40: 全新 | J40: 首 | L40: 留存 | M40: 60 | R40: 闲鱼
...

Sheet 淘宝
A1: IP | B1: 系列名称 | C1: 名称 | D1: 买时状态 | E1: 状态 | F1: 总价 | G1: 成本价格 | H1: 卖出价格 | I1: 利润 | J1: 利润率 | K1: 备注
A2: 龙珠 | B2: HG | C2: 沙鲁全形态 | D2: 全新 | E2: 留存 | F2: 635 | K2: 预定 | M2: 总花销 | N2: =SUM(F:F) -> 19048
A3: 曼达洛人 | B3: FRS | C3: 贝斯卡金属盔甲 | D3: 全新 | E3: 留存 | F3: 275 | M3: 总卖出 | N3: =SUM(H:H) -> 7342
A4: 龙珠 | B4: SHF | C4: 婴儿车弗利萨 | D4: 全新 | E4: 留存 | F4: 444 | K4: 预定，已拆 | M4: 总卖出成本 | N4: =SUM(G:G) -> 5819
A5: 龙珠 | B5: HG | C5: 弗利萨全形态 | D5: 全新 | E5: 留存 | F5: 820 | K5: 预定 | M5: 利润 | N5: =SUM(I:I) -> 1523
A6: 龙珠 | B6: 桌面系列 | C6: 悟空全形态 | D6: 全新 | E6: 留存 | F6: 400 | K6: 预定 | M6: 利润率 | N6: =ROUND(N5/N3,4) -> 0.2074
A7: 龙珠 | B7: FiguartsZERO | C7: 超3龙拳 | D7: 全新 | E7: 留存 | F7: 653 | K7: 新版预定，已拆 | M7: 实际支出 | N7: =N2-N3 -> 11706
A8: 数码宝贝 | B8: FRS | C8: 机械暴龙兽 | D8: 全新 | E8: 留存 | F8: 277 | K8: 预定
A9: 龙珠 | B9: 出阵 | C9: 比克A款 | D9: 全新 | E9: 留存 | F9: 106 | K9: 预定
A10: 龙珠 | B10: 出阵 | C10: 比克B款 | D10: 全新 | E10: 留存 | F10: 104 | K10: 预定
A11: 龙珠 | B11: Gxmateria | C11: 超赛贝吉特 | D11: 全新 | E11: 留存 | F11: 51
A12: 龙珠 | B12: 出阵 | C12: 超赛特兰克斯 | D12: 全新 | E12: 留存 | F12: 51
A13: 龙珠 | B13: Gxmateria | C13: 短笛 魔贯光杀炮 | D13: 全新 | E13: 留存 | F13: 51
A14: 龙珠 | B14: LC | C14: 发波悟空 | D14: 全新 | E14: 留存 | F14: 148
A15: 龙珠 | B15: FES | C15: 12悟空 | D15: 全新 | E15: 留存 | F15: 82
A16: 龙珠 | B16: Grandista | C16: 孙悟饭 | D16: 全新 | E16: 留存 | F16: 194
A17: 龙珠 | B17: Grandista | C17: 超3悟空 | D17: 全新 | E17: 留存 | F17: 686
A18: 龙珠 | B18: 一番赏 | C18: 羁绊黑发贝吉塔 | D18: 全新 | E18: 留存 | F18: 380
A19: 龙珠 | B19: 一番赏 | C19: 羁绊黑发悟空 | D19: 全新 | E19: 留存 | F19: 312
A20: 龙珠 | C20: 水晶球 | D20: 全新 | E20: 留存 | F20: 51
A21: 龙珠 | B21: FiguartsZERO | C21: 邪念波 | D21: 全新 | E21: 留存 | F21: 709 | K21: 预定
A22: 龙珠 | B22: PLEX | C22: 拉蒂兹 | D22: 全新 | E22: 留存 | F22: 1698 | K22: 预定
A23: 更衣人偶坠入爱河 | B23: Taito | C23: 喜多川海梦 | D23: 全新 | E23: 留存 | F23: 252 | K23: 130重涂
A24: 龙珠 | B24: WCF | C24: 宝藏1 | D24: 全新 | E24: 卖出 | F24: 962 | G24: 802 | H24: 1219 | I24: =H24-G24 -> 417 | J24: =I24/G24 -> 0.51995012 | K24: 6件，留一件
A25: 鬼灭之刃 | B25: WCF | C25: 善逸 | D25: 全新 | E25: 卖出 | F25: 402 | G25: 268 | H25: 328 | I25: =H25-G25 -> 60 | J25: =I25/G25 -> 0.2238806 | K25: 3件，留一件
A26: 鬼灭之刃 | B26: WCF | C26: 伊之助 | D26: 全新 | E26: 卖出 | F26: 470 | G26: 344 | H26: 484 | I26: =H26-G26 -> 140 | J26: =I26/G26 -> 0.40697674 | K26: 3件，还剩一件除女装的四个
A27: 龙珠 | B27: 历史盒子 | C27: 超赛悟空2 | D27: 全新 | E27: 留存 | F27: 63
A28: 龙珠 | B28: BOS | C28: 未来悟饭 | D28: 全新 | E28: 卖出 | F28: 33 | G28: 33 | H28: 44 | I28: =H28-G28 -> 11 | J28: =I28/G28 -> 0.33333333
A29: 龙珠 | B29: 出阵 | C29: 悟饭 | D29: 全新 | E29: 卖出 | F29: 39 | G29: 39 | H29: 59 | I29: =H29-G29 -> 20 | J29: =I29/G29 -> 0.51282051
A30: 龙珠 | B30: 出阵 | C30: 比克 | D30: 全新 | E30: 卖出 | F30: 39 | G30: 39 | H30: 76 | I30: =H30-G30 -> 37 | J30: =I30/G30 -> 0.94871795
A31: 龙珠 | B31: 出阵 | C31: 悟饭 | D31: 全新 | E31: 卖出 | F31: 33 | G31: 33 | H31: 60 | I31: =H31-G31 -> 27 | J31: =I31/G31 -> 0.81818182
A32: 鬼灭之刃 | B32: WCF | C32: 主公大人面前2 | D32: 全新 | E32: 留存 | F32: 81
A33: 我与机器子 | B33: megahouse | C33: 机器子 | D33: 全新 | E33: 留存 | F33: 588
A34: 无职转生 | B34: 换装时刻 | C34: 红妈妈 | D34: 全新 | E34: 留存 | F34: 862
A35: 啦啦队系列 | B35: Hobby·sakura | C35: 阿雅 | D35: 全新 | E35: 卖出 | F35: 598 | G35: 598 | H35: 693 | I35: =H35-G35 -> 95 | J35: =I35/G35 -> 0.15886288 | K35: 普通版
A36: 啦啦队系列 | B36: Hobby·sakura | C36: 阿雅 | D36: 全新 | E36: 卖出 | F36: 598 | G36: 598 | H36: 595 | I36: =H36-G36 -> -3 | J36: =I36/G36 -> -0.0050167224 | K36: 普通版
A37: 啦啦队系列 | B37: Hobby·sakura | C37: 阿雅 | D37: 全新 | E37: 留存 | F37: 598 | K37: 普通版，卖
A38: 共鸣 | B38: 泡泡玛特 | C38: 龙珠载具系列 | D38: 全新 | E38: 留存 | F38: 469
A39: 初音未来 | B39: GSC | C39: 牛角初音 | D39: 全新 | E39: 留存 | F39: 819 | K39: GSC淘宝旗舰店
A40: 黑岩射手 | B40: Max Factory | C40: 黑岩射手 | D40: 全新 | E40: 卖出 | F40: 1291 | G40: 1291 | H40: 1674 | I40: =H40-G40 -> 383 | J40: =I40/G40 -> 0.29666925 | K40: 天猫国际，未发货补偿
...

Sheet B站市集
A1: IP | B1: 系列名称 | C1: 名称 | D1: 买时状态 | E1: 购入价格 | F1: 状态 | G1: 总价 | H1: 卖出成本 | I1: 卖出价格 | J1: 利润 | K1: 利润率 | L1: 备注
A2: 狐妖小红娘 | B2: 盛夏绽放 泳装Ver. | C2: 涂山红红 | D2: 全新 | E2: 232 | F2: 卖出 | G2: =E2 -> 232 | H2: 232 | I2: 510 | J2: =I2-H2 -> 278 | K2: =J2/H2 -> 1.1982759 | N2: 总花销 | O2: =SUM(G:G) -> 8307
A3: 狐妖小红娘 | B3: 初见 手游版 | C3: 涂山苏苏 | D3: 全新 | E3: 189 | F3: 卖出 | G3: =E3 -> 189 | H3: 189 | I3: 328 | J3: =I3-H3 -> 139 | K3: =J3/H3 -> 0.73544974 | N3: 总卖出 | O3: =SUM(I:I) -> 1406
B4: 阿尔维娜 | C4: 阿尔维娜 | D4: 全新 | E4: 390 | F4: 留存 | G4: =E4 -> 390 | N4: 总卖出成本 | O4: =SUM(H:H) -> 846
A5: 少女前线 | C5: 她从雨中来 | D5: 全新 | E5: 550 | F5: 留存 | G5: =E5 -> 550 | N5: 利润 | O5: =SUM(J:J) -> 560
A6: 碧蓝航线 | B6: GSC | C6: 尾张 | D6: 全新 | E6: 763 | F6: 留存 | G6: =E6 -> 763 | L6: 25年9月 | N6: 利润率 | O6: =ROUND(O5/O4,4) -> 0.6619
B7: GSC | C7: 白银诺艾尔 泳装 | D7: 全新 | E7: 725 | F7: 留存 | G7: =E7 -> 725 | L7: 25年7月 | N7: 实际支出 | O7: =O2-O3 -> 6901
A8: 碧蓝航线 | B8: Mimeyoi | C8: 约克公爵 | D8: 全新 | E8: 705 | F8: 留存 | G8: =E8 -> 705
C9: 金瓯永固杯 | D9: 全新 | E9: 320 | F9: 卖出 | G9: =E9 -> 320 | H9: 320 | I9: 360 | J9: =I9-H9 -> 40 | K9: =J9/H9 -> 0.125
B10: 尺玉 | C10: 雪乃深冬 | D10: 全新 | E10: 480 | F10: 留存 | G10: =E10 -> 480 | L10: 25年12月
A11: 电锯人 | B11: BiCute Bunnies | C11: 蕾塞 | D11: 全新 | E11: 105 | F11: 卖出 | G11: =E11 -> 105 | H11: 105 | I11: 208 | J11: =I11-H11 -> 103 | K11: =J11/H11 -> 0.98095238 | L11: 26年1月
A12: 电锯人 | B12: BiCute Bunnies | C12: 蕾塞 | D12: 全新 | E12: 98 | F12: 留存 | G12: =E12 -> 98 | L12: 26年1月
A13: 约会大作战 | B13: 角川 | C13: 时崎狂三 富士见文库30周年纪念版 | D13: 全新 | E13: 710 | F13: 留存 | G13: =E13 -> 710 | L13: 26年2月
A14: EVA | B14: Alter | C14: 绫波丽 | D14: 全新 | E14: 900 | F14: 留存 | G14: =E14 -> 900 | L14: 26年2月
A15: 更衣人偶坠入爱河 | B15: GSC | C15: 喜多川海梦 黑江雫 | D15: 全新 | E15: 693 | F15: 留存 | G15: =E15 -> 693 | L15: 26年3月
A16: 鬼灭之刃 | B16: Alter | C16: 富冈义勇 | D16: 全新 | E16: 836 | F16: 留存 | G16: =E16 -> 836 | L16: 26年6月，闲鱼购入
A17: 电锯人 | B17: S-FIRE | C17: 蕾塞 | D17: 全新 | E17: 611 | F17: 留存 | G17: =E17 -> 611 | L17: 26年9月

Sheet 小程序
A1: IP | B1: 系列名称 | C1: 名称 | D1: 买时状态 | E1: 状态 | F1: 总价 | G1: 成本价格 | H1: 卖出价格 | I1: 利润 | J1: 利润率 | K1: 备注
A2: GSC | C2: 02国家队+少女前线DSR-50 | D2: 全新 | E2: 卖出 | F2: 899 | G2: 899 | H2: 1440 | I2: =H2-G2 -> 541 | J2: =I2/G2 -> 0.60177976 | K2: 福袋 | M2: 总花销 | N2: =SUM(F:F) -> 1797
A3: BANDAI | B3: SMSP | C3: 贝吉塔 | D3: 全新 | E3: 留存 | F3: 449 | M3: 总卖出 | N3: =SUM(H:H) -> 1440
A4: BANDAI | B4: SMSP | C4: 悟空 | D4: 全新 | E4: 留存 | F4: 449 | K4: 胖猪号 | M4: 总卖出成本 | N4: =SUM(G:G) -> 899
M5: 利润 | N5: =SUM(I:I) -> 541
M6: 利润率 | N6: =ROUND(N5/N4,4) -> 0.6018
M7: 实际支出 | N7: =N2-N3 -> 357

Sheet 入魂一番赏
A1: IP | B1: 系列名称 | C1: 名称 | D1: 买时状态 | E1: 状态 | F1: 总价 | G1: 卖出成本 | H1: 卖出价格 | I1: 利润 | J1: 利润率 | K1: 备注
A2: 约会大作战 | B2: GSC POP UP | C2: 时崎狂三 校服 L尺寸 | D2: 全新 | E2: 卖出 | F2: 240 | G2: 240 | H2: 285 | I2: =H2-G2 -> 45 | J2: =I2/G2 -> 0.1875 | K2: 24年10月 | M2: 总花销 | N2: =SUM(F:F) -> 10445
A3: 四月是你的谎言 | B3: GSC | C3: 宫园薰 | D3: 全新 | E3: 留存 | F3: 450 | K3: 24年11月 | M3: 总卖出 | N3: =SUM(H:H) -> 1121
A4: 初音未来 | B4: GSC | C4: 樱花未来 赏花装扮 | D4: 全新 | E4: 留存 | F4: 755 | K4: 25年4月 | M4: 总卖出成本 | N4: =SUM(G:G) -> 1005
A5: 蔚蓝档案 | B5: GSC | C5: 月雪宫子 | D5: 全新 | E5: 留存 | F5: 360 | K5: 25年5月 | M5: 利润 | N5: =SUM(I:I) -> 116
A6: 龙珠 | B6: 一番赏 | C6: 9号胶囊机车 | D6: 全新 | E6: 留存 | F6: 520 | K6: 25年1月 | M6: 利润率 | N6: =ROUND(N5/N4,4) -> 0.1154
A7: 龙珠 | B7: 一番赏 | C7: 比克大魔王last | D7: 全新 | E7: 留存 | F7: 750 | M7: 实际支出 | N7: =N2-N3 -> 9324
A8: 龙珠 | B8: 一番赏 | C8: 贝比 | D8: 全新 | E8: 留存 | F8: 230
A9: 龙珠 | B9: FiguartsZERO | C9: 大魔 界王神 | D9: 全新 | E9: 留存 | F9: 580
A10: 龙珠 | B10: Gxmateria | C10: 巴达克 | D10: 全新 | E10: 留存 | F10: 50
A11: 龙珠 | B11: 出阵 | C11: 人造人16号 | D11: 全新 | E11: 留存 | F11: 58
A12: 龙珠 | B12: 出阵 | C12: 弗利萨 | D12: 全新 | E12: 留存 | F12: 85
A13: 龙珠 | B13: 一番赏 | C13: 大魔 贝吉塔 布玛B赏 | D13: 全新 | E13: 留存 | F13: 90
A14: 龙珠 | B14: 一番赏 | C14: 大魔 比克 丹迪C赏 | D14: 全新 | E14: 留存 | F14: 180
A15: 龙珠 | B15: 一番赏 | C15: 大魔 古罗里奥D赏 | D15: 全新 | E15: 留存 | F15: 80
A16: 龙珠 | B16: 一番赏 | C16: 布尔玛 | D16: 全新 | E16: 留存 | F16: 107 | K16: 修业篇
A17: 龙珠 | B17: 一番赏 | C17: 雅木茶 | D17: 全新 | E17: 留存 | F17: 184 | K17: 修业篇
A18: 龙珠 | B18: 一番赏 | C18: 库林&悟空 | D18: 全新 | E18: 留存 | F18: 200 | K18: 修业篇
A19: 龙珠 | B19: 一番赏 | C19: 龟仙人 | D19: 全新 | E19: 留存 | F19: 315 | K19: 修业篇
A20: 龙珠 | B20: 一番赏 | C20: LAST立牌 | D20: 全新 | E20: 留存 | F20: 360 | K20: 少年篇
A21: 龙珠 | B21: 一番赏 | C21: 海龟 | D21: 全新 | E21: 留存 | F21: 55 | K21: 少年篇
A22: 龙珠 | B22: 一番赏 | C22: 库林 | D22: 全新 | E22: 留存 | F22: 78 | K22: 少年篇
A23: 龙珠 | B23: 一番赏 | C23: 立牌 | D23: 全新 | E23: 留存 | F23: 40 | K23: 少年篇 一整套
A24: 龙珠 | B24: 一番赏 | C24: 占卜婆婆 | D24: 全新 | E24: 留存 | F24: 62 | K24: 少年篇
A25: 龙珠 | B25: 一番赏 | C25: 亚奇洛贝 | D25: 全新 | E25: 留存 | F25: 55 | K25: 少年篇
A26: 龙珠 | B26: 一番赏 | C26: 阿修 | D26: 全新 | E26: 留存 | F26: 58 | K26: 少年篇
A27: 龙珠 | B27: 一番赏 | C27: 小舞 | D27: 全新 | E27: 留存 | F27: 58 | K27: 少年篇 乌龙换的
... A37: 龙珠 | B37: 一番赏 | C37: 立牌 | D37: 全新 | E37: 留存 | F37: 3 | K37: CROSS H赏
A38: 龙珠 | B38: FiguartsZERO | C38: 战斗的轨迹 | D38: 全新 | E38: 留存 | F38: 401
A39: 龙珠 | B39: 一番赏 | C39: 悟饭 | D39: 全新 | E39: 留存 | F39: 190 | K39: 40周年 其二
A40: 龙珠 | B40: 一番赏 | C40: 库林 | D40: 全新 | E40: 留存 | F40: 255 | K40: 40周年 其二
A41: 龙珠 | B41: 一番赏 | C41: 贝吉塔 | D41: 全新 | E41: 留存 | F41: 190 | K41: 40周年 其二
A42: 龙珠 | B42: 一番赏 | C42: 比克 | D42: 全新 | E42: 留存 | F42: 300 | K42: 40周年 其二
A43: 龙珠 | B43: 一番赏 | C43: A悟空+Last神龙 | D43: 全新 | E43: 留存 | F43: 590 | K43: 40周年 其二
A44: 龙珠 | B44: 一番赏 | C44: LAST | D44: 全新 | E44: 留存 | F44: 426 | K44: 载具2篇
A45: 龙珠 | B45: BOS | C45: 超级赛亚人 孙悟饭Ⅱ | D45: 全新 | E45: 留存 | F45: 55
A46: 龙珠 | B46: 历史盒子 | C46: 胖布欧 | D46: 全新 | E46: 留存 | F46: 55
A47: 龙珠 | B47: 历史盒子 | C47: 布尔玛 | D47: 全新 | E47: 留存 | F47: 70
A48: 龙珠 | B48: 一番赏 | C48: LAST | D48: 全新 | E48: 卖出 | F48: 365 | G48: 365 | H48: 396 | I48: =H48-G48 -> 31 | J48: =I48/G48 -> 0.084931507 | K48: 红缎带军团
A49: 龙珠 | B49: 一番赏 | C49: D赏 潜水艇 | D49: 全新 | E49: 卖出 | F49: 400 | G49: 400 | H49: 440 | I49: =H49-G49 -> 40 | J49: =I49/G49 -> 0.1 | K49: 红缎带军团

Sheet 总计
A1: 总花销 | B1: =SUM(日淘!R3+闲鱼!P2+泡泡玛特!O2+并夕夕!N2+预定!Q2+抖音!N2+'套书+单行本'!W2+'散本+未完结'!U2+淘宝!N2+B站市集!O2+小程序!N2+入魂一番赏!N2) -> 472297
A2: 总卖出 | B2: =SUM(日淘!R4+闲鱼!P3+泡泡玛特!O3+并夕夕!N3+预定!Q3+抖音!N3+'套书+单行本'!W3+'散本+未完结'!U3+淘宝!N3+B站市集!O3+小程序!N3+入魂一番赏!N3) -> 171519
A3: 总卖出成本 | B3: =SUM(日淘!R5+闲鱼!P4+泡泡玛特!O4+并夕夕!N4+预定!Q4+抖音!N4+'套书+单行本'!W4+'散本+未完结'!U4+淘宝!N4+B站市集!O4+小程序!N4+入魂一番赏!N4) -> 145530
A4: 利润 | B4: =SUM(日淘!R6+闲鱼!P5+泡泡玛特!O5+并夕夕!N5+预定!Q5+抖音!N5+'套书+单行本'!W5+'散本+未完结'!U5+淘宝!N5+B站市集!O5+小程序!N5+入魂一番赏!N5) -> 25989
A5: 利润率 | B5: =ROUND(B4/B3,4) -> 0.1786
A6: 实际支出 | B6: =SUM(日淘!R8+闲鱼!P7+泡泡玛特!O7+并夕夕!N7+预定!Q7+抖音!N7+'套书+单行本'!W7+'散本+未完结'!U7+淘宝!N7+B站市集!O7+小程序!N7+入魂一番赏!N7) -> 300778
